### 문제 
> 다음 예상 되는 결과는?

```javascript
try {
  setTimeout(() => { throw new Error('Error!'); }, 1000);
} catch (e) {
  console.error('캐치한 에러', e);
}
```

#### 정답
> Uncaught Error: Error!
> 브라우저 에러발생

##### 해설
[제너레이터와 async/await](https://github.com/YangGwangSeong/TIL)

> 에러는 호출자(caller) 방향으로 전파된다. 즉, 콜 스택의 아래 방향(실행 중인 실행 컨텍스트가 푸시되기 직전에 푸시된 실행 컨텍스트 방향)으로 전파된다.
> 하지만 비동기 함수의 콜백 함수를 호출한 것은 비동기 함수가 아니기 때문에 try ... catch 문을 사용해 에러를 캐치할 수 없다.




